<?xml version="1.0" ?>

<robot name="rb1_robot">

    <material name="blue">
        <color rgba="0 0 1 1"/>
    </material>

    <material name="gray">
        <color rgba="0.40 0.40 0.40 1"/>
    </material>

    <material name="red">
        <color rgba="1 0 0 1"/>
    </material>

    <link name="base_footprint">
    </link>

    <joint name="base_link_plate_joint" type="fixed">
        <origin rpy="0 0 0" xyz="0 0 0.15" />
        <parent link="base_footprint" />
        <child link="base_link" />
    </joint>

    <link name="base_link">
        <visual>
            <origin xyz="0 0 0" rpy="0 0 0"/>
            <geometry>
                <cylinder radius="0.25" length="0.3"/>
            </geometry>
            <material name="blue"/>
        </visual>
        <collision>
            <origin xyz="0 0 0" rpy="0 0 0"/>
            <geometry>
                <cylinder radius="0.25" length="0.3"/>
            </geometry>
        </collision>
        <inertial>
            <mass value="20.5" />
            <origin xyz="0 0 0" rpy="0 0 0" />
            <inertia ixx="0.47406249999999994" ixy="0.0" ixz="0.0" iyy="0.47406249999999994" iyz="0.0" izz="0.640625" />
        </inertial>
    </link>

    <link name="left_wheel">
        <visual>
            <origin xyz="0 0 0" rpy="-1.575 0 0"/>
            <geometry>
                <cylinder radius="0.025" length="0.03"/>
            </geometry>
            <material name="red"/>
        </visual>
        <collision>
            <origin xyz="0 0 0" rpy="-1.575 0 0"/>
            <geometry>
                <cylinder radius="0.025" length="0.03"/>
            </geometry>
        </collision>
        <inertial>
            <mass value="1.5" />
            <origin xyz="0 0 0" rpy="-1.575 0 0" />
            <inertia ixx="0.00034687500000000007" ixy="0.0" ixz="0.0" iyy="0.00034687500000000007" iyz="0.0" izz="0.0004687500000000001" />
        </inertial>
    </link>

    <joint name="base_link_left_wheel_joint" type="continuous">
        <origin rpy="0 0 0" xyz="0 -0.2 -0.15" />
        <parent link="base_link" />
        <child link="left_wheel" />
    </joint>

    <link name="right_wheel">
        <visual>
            <origin xyz="0 0 0" rpy="-1.575 0 0"/>
            <geometry>
                <cylinder radius="0.025" length="0.03"/>
            </geometry>
            <material name="red"/>
        </visual>
        <collision>
            <origin xyz="0 0 0" rpy="-1.575 0 0"/>
            <geometry>
                <cylinder radius="0.025" length="0.03"/>
            </geometry>
        </collision>
        <inertial>
            <mass value="1.5" />
            <origin xyz="0 0 0" rpy="-1.575 0 0" />
            <inertia ixx="0.00034687500000000007" ixy="0.0" ixz="0.0" iyy="0.00034687500000000007" iyz="0.0" izz="0.0004687500000000001" />
        </inertial>
    </link>

    <joint name="base_link_right_wheel_joint" type="continuous">
        <origin rpy="0 0 0" xyz="0 0.2 -0.15" />
        <parent link="base_link" />
        <child link="right_wheel" />
    </joint>

    <link name="front_caster">
        <visual>
            <origin xyz="0 0 0" rpy="0 0 0" />
            <geometry>
                <sphere radius="0.025" />
            </geometry>
            <material name="gray"/>
        </visual>
        <collision>
            <origin xyz="0 0 0" rpy="0 0 0" />
            <contact_coefficients mu="0.0" kp="0.0" kd="0.0" />
            <geometry>
                <sphere radius="0.025" />
            </geometry>
        </collision>
        <inertial>
            <mass value="0.5" />
            <origin xyz="0 0 0" rpy="0 0 0" />
            <inertia ixx="0.00012500000000000003" ixy="0.0" ixz="0.0" iyy="0.00012500000000000003" iyz="0.0" izz="0.00012500000000000003" />
        </inertial>
    </link>

    <joint name="base_link_front_caster_joint" type="fixed">
        <parent link="base_link"/>
        <child link="front_caster"/>
        <origin xyz="-0.1 0.0 -0.15" rpy="0 0 0"/>
    </joint>

    <link name="back_caster">
        <visual>
            <origin xyz="0 0 0" rpy="0 0 0" />
            <geometry>
                <sphere radius="0.025" />
            </geometry>
            <material name="gray"/>
        </visual>
        <collision>
            <origin xyz="0 0 0" rpy="0 0 0" />
            <contact_coefficients mu="0.0" kp="0.0" kd="0.0" />
            <geometry>
                <sphere radius="0.025" />
            </geometry>
        </collision>
        <inertial>
            <mass value="0.5" />
            <origin xyz="0 0 0" rpy="0 0 0" />
            <inertia ixx="0.00012500000000000003" ixy="0.0" ixz="0.0" iyy="0.00012500000000000003" iyz="0.0" izz="0.00012500000000000003" />
        </inertial>
    </link>

    <joint name="base_link_back_caster_joint" type="fixed">
        <parent link="base_link"/>
        <child link="back_caster"/>
        <origin xyz="0.1 0.0 -0.15" rpy="0 0 0"/>
    </joint>

    <link name="front_laser">
        <visual>
            <origin xyz="0 0 0" rpy="0 0 0"/>
            <geometry>
                <cylinder radius="0.03" length="0.02"/>
            </geometry>
            <material name="red"/>
        </visual>
        <collision>
            <origin xyz="0 0 0" rpy="0 0 0"/>
            <geometry>
                <cylinder radius="0.03" length="0.02"/>
            </geometry>
        </collision>
        <inertial>
            <mass value="0.5" />
            <origin xyz="0 0 0" rpy="0 0 0" />
            <inertia ixx="0.00012916666666666667" ixy="0.0" ixz="0.0" iyy="0.00012916666666666667" iyz="0.0" izz="0.000225" />
        </inertial>
    </link>

    <joint name="base_link_front_laser_joint" type="fixed">
        <origin rpy="3.14 0 0" xyz="0.25 0 0.075" />
        <parent link="base_link" />
        <child link="front_laser" />
    </joint>

    <gazebo reference="base_link">
        <material>Gazebo/Black</material>
    </gazebo>

    <gazebo reference="left_wheel">
        <material>Gazebo/Red</material>
    </gazebo>

    <gazebo reference="right_wheel">
        <material>Gazebo/Red</material>
    </gazebo>

    <gazebo reference="front_caster">
        <material>Gazebo/Gray</material>
    </gazebo>

    <gazebo reference="back_caster">
        <material>Gazebo/Gray</material>
    </gazebo>

    <gazebo reference="front_laser">
        <material>Gazebo/Red</material>
    </gazebo>
</robot>
